<?xml version="1.0" ?>
<robot name="wheeltec_robot">
    <link name="base_footprint" />

    <link name="base_link">
        <inertial>
            <mass value="5.0"/>
            <origin xyz="0 0 0"/>
            <inertia ixx="0.1" ixy="0.0" ixz="0.0" iyy="0.1" iyz="0.0" izz="0.1"/>
        </inertial>
        <visual>
            <origin xyz=" 0 0 0.205" rpy="0 0 0" />
            <geometry>
                <box size="1.08 0.76 0.05"/>
            </geometry>
            <material name="white">
                <color rgba="1 1 1 1"/>
            </material>
        </visual>
    </link>

    <joint name="base_footprint_to_base_link" type="fixed">
        <parent link="base_footprint"/>
        <child link="base_link"/>
        <origin xyz="0 0 0" rpy="0 0 0"/>
    </joint>   

    <joint name="left_wheel_joint" type="continuous">
        <origin xyz="-0.325 0.3285 0.09" rpy="1.57 0 0"/> <!-- ivan change -->
        <parent link="base_link"/>
        <child link="left_wheel_link"/>
        <axis xyz="0 0 1"/>
    </joint>

    <link name="left_wheel_link">
        <inertial>
            <mass value="1.0"/>
            <origin xyz="0 0 0"/>
            <inertia ixx="0.01" ixy="0.0" ixz="0.0" iyy="0.01" iyz="0.0" izz="0.01"/>
        </inertial>
        <visual>
            <origin xyz="0 0 0" rpy="0 0 0" />
            <geometry>
                <cylinder radius="0.09" length = "0.073"/> <!-- ivan change -->
            </geometry>
            <material name="black">
                <color rgba="0 0 0 1"/>
            </material>
        </visual>
    </link>

    <joint name="right_wheel_joint" type="continuous">
        <origin xyz="-0.325 -0.3285 0.09" rpy="1.57 0 0"/> <!-- ivan change -->
        <parent link="base_link"/>
        <child link="right_wheel_link"/>
        <axis xyz="0 0 1"/>
    </joint>

    <link name="right_wheel_link">
        <inertial>
            <mass value="1.0"/>
            <origin xyz="0 0 0"/>
            <inertia ixx="0.01" ixy="0.0" ixz="0.0" iyy="0.01" iyz="0.0" izz="0.01"/>
        </inertial>
        <visual>
            <origin xyz="0 0 0" rpy="0 0 0" />
            <geometry>
                <cylinder radius="0.09" length = "0.073"/> <!-- ivan change -->
            </geometry>
            <material name="black">
                <color rgba="0 0 0 1"/>
            </material>
        </visual>
    </link>

      <joint name="left_front_joint" type="continuous">
        <origin xyz="0.325 0.3285 0.09" rpy="1.57 0 0"/> <!-- ivan change -->
        <parent link="base_link"/>
        <child link="left_front_link"/>
        <axis xyz="0 0 1"/>
    </joint>

    <link name="left_front_link">
        <inertial>
            <mass value="1.0"/>
            <origin xyz="0 0 0"/>
            <inertia ixx="0.01" ixy="0.0" ixz="0.0" iyy="0.01" iyz="0.0" izz="0.01"/>
        </inertial>
        <visual>
            <origin xyz="0 0 0" rpy="0 0 0" />
            <geometry>
                <cylinder radius="0.09" length = "0.073"/> <!-- ivan change -->
            </geometry>
            <material name="black">
                <color rgba="0 0 0 1"/>
            </material>
        </visual>
    </link>

    <joint name="right_front_joint" type="continuous">
        <origin xyz="0.325 -0.3285 0.09" rpy="1.57 0 0"/> <!-- ivan change -->
        <parent link="base_link"/>
        <child link="right_front_link"/>
        <axis xyz="0 0 1"/>
    </joint>

    <link name="right_front_link">
        <inertial>
            <mass value="1.0"/>
            <origin xyz="0 0 0"/>
            <inertia ixx="0.01" ixy="0.0" ixz="0.0" iyy="0.01" iyz="0.0" izz="0.01"/>
        </inertial>
        <visual>
            <origin xyz="0 0 0" rpy="0 0 0" />
            <geometry>
                <cylinder radius="0.09" length = "0.073"/> <!-- ivan change -->
            </geometry>
            <material name="black">
                <color rgba="0 0 0 1"/>
            </material>
        </visual>
    </link>


</robot>
