<?xml version="1.0" ?>
<robot name="wheeltec_robot" xmlns:xacro="http://www.ros.org/wiki/xacro">

    <!-- base_footprint (固定到 base_link) -->
    <link name="base_footprint"/>
    <joint name="base_footprint_joint" type="fixed">
        <origin xyz="0 0 0" rpy="0 0 0"/>
        <parent link="base_footprint"/>
        <child link="base_link"/>
    </joint>

    <!-- 底盤 -->
    <link name="base_link">
        <inertial>
            <mass value="10.0"/>
            <origin xyz="0 0 0" />
            <inertia ixx="0.1" ixy="0.0" ixz="0.0" iyy="0.1" iyz="0.0" izz="0.2"/>
        </inertial>
        <visual>
            <origin xyz="0 0 0.105" rpy="0 0 0" />
            <geometry>
                <box size="1.08 0.577 0.1"/>
            </geometry>
            <material name="white">
                <color rgba="1 1 1 1"/>
            </material>
        </visual>
        <collision>
            <origin xyz="0 0 0.105" rpy="0 0 0"/>
            <geometry>
                <box size="1.08 0.577 0.13"/>
            </geometry>
        </collision>
    </link>

    <!-- Gazebo 控制插件 -->
    <gazebo>
        <plugin name="gazebo_ros2_control" filename="libgazebo_ros2_control.so">
            <parameters>$(find wheeltec_robot_urdf)/config/gazebo_controllers.yaml</parameters>
        </plugin>
    </gazebo>
    
    <!-- ROS2 控制設定 -->
    <ros2_control name="wheeltec_robot_control" type="system">
        <hardware>
            <plugin>gazebo_ros2_control/GazeboSystem</plugin>
        </hardware>

        <joint name="left_wheel_joint">
            <command_interface name="velocity"/>
            <state_interface name="velocity"/>
        </joint>

        <joint name="right_wheel_joint">
            <command_interface name="velocity"/>
            <state_interface name="velocity"/>
        </joint>

        <joint name="left_front_joint">
            <command_interface name="velocity"/>
            <state_interface name="velocity"/>
        </joint>

        <joint name="right_front_joint">
            <command_interface name="velocity"/>
            <state_interface name="velocity"/>
        </joint>
    </ros2_control>

    <!-- 四個輪子修正 -->
    <xacro:macro name="wheel" params="name x y">
        <joint name="${name}_joint" type="continuous">
            <origin xyz="${x} ${y} 0.09" rpy="1.5708 0 0"/>  <!-- 修正 rpy，讓輪子與地面對齊 -->
            <parent link="base_link"/>
            <child link="${name}_link"/>
            <axis xyz="0 0 1"/>  <!-- 讓輪子圍繞 Z 軸旋轉 -->
        </joint>

        <link name="${name}_link">
            <inertial>
                <mass value="2.0"/>
                <origin xyz="0 0 0"/>
                <inertia ixx="0.01" ixy="0.0" ixz="0.0" iyy="0.01" iyz="0.0" izz="0.02"/>
            </inertial>
            <visual>
                <origin xyz="0 0 0" rpy="0 0 0"/>
                <geometry>
                    <cylinder radius="0.09" length="0.073"/>
                </geometry>
                <material name="black">
                    <color rgba="0 0 0 1"/>
                </material>
            </visual>
            <collision>
                <origin xyz="0 0 0" rpy="0 0 0"/>
                <geometry>
                    <cylinder radius="0.09" length="0.073"/>
                </geometry>
            </collision>
        </link>

        <gazebo reference="${name}_joint">
            <mu1>0.9</mu1>
            <mu2>0.9</mu2>
            <kp>100000</kp>
            <kd>10</kd>
        </gazebo>
    </xacro:macro>

    <!-- 修正 mecanum 輪的正確位置 -->
    <xacro:wheel name="left_wheel" x="-0.325" y="0.3285"/>
    <xacro:wheel name="right_wheel" x="-0.325" y="-0.3285"/>
    <xacro:wheel name="left_front" x="0.325" y="0.3285"/>
    <xacro:wheel name="right_front" x="0.325" y="-0.3285"/>

</robot>
